Workbook

Sheet Changelog
A1: Version | B1: Date | C1: Notes | D1: Links
C2: Remember you need to download or copy the document before using it! Toolbar -> File -> Make a copy/Download This way you'll be able to change cell values in your own copy. Please DO NOT use cell comments to mark your progress by writing something like Y/N/Done/Yes/No, those are for feedback. | D2: =hyperlink("https://docs.google.com/spreadsheets/d/1W4P83Y9umpGs8DX9VtzXngE-Knhv8sndDhj1QpBIYUA/edit?usp=sharing" , "Link to main google sheet (If you're using web view or need a link to the main document use this)") -> Link to main google sheet (If you're using web view or need a link to the main document use this)
C3: Comments are open to everyone feel free to make suggestions or suggest fixes. Check the feedback and todo page first. | D3: =HYPERLINK("https://docs.google.com/spreadsheets/d/e/2PACX-1vSE_QojDmDDLYDmNQuy4Lkpl2PrJ_NB7DoCbMYJ_E8xFgKoBgMjNmWf1oiHz2Of9eQYrIpFdzQVgbw1/pubhtml", "Link to web view (Page loads much faster but CAN'T be copied or edited! Useful if you just want to use it as a refrence)") -> Link to web view (Page loads much faster but CAN'T be copied or edited! Useful if you just want to use it as a refrence)
A4: 1.1 | B4: 45606 | C4: Added perks gained from quests. Minor formatting changes and corrections
A5: 1.0 (finally) | B5: 45603 | C5: Added Anniversary Edition (CC) Quests. Added the percentages to track quests progession. Added Aniversary Edition (CC) Spells, Enchanting Effects, Alchemy ingrediants and Locations Alchemy Tab has been reorganized and list ingrediants effect duration and value multipliers if they have one. Also lists if the ingrediant is growable and how many are harvested this way Redid the formulas a bit so thay should be fine if you delete any Aniversary Edition content. I probably made some mistakes let me know if you see any.
B6: 44446 | C6: Added some quest items that can be pickpocketed back after completion.
B7: 44444 | C7: Unique horses added to Followers tab Fjola's Wedding Band added to Vanilla uniques Filters for sorting added
B8: 44438 | C8: Minor fixes to books tab. Added notes to a couple books with two versions Added notes to quest books that can be pickpocketed back Changed name of the book "The "Madmen" of the Reach to contain quotes Smithing perks notes fixed Fixed a lot of misprints on the Enchantments tab
B9: 44433 | C9: Added perk trees for Werewolf and Vampire Lord Bone hawk ring and amulet are removed from unique gear - craftable Enchanted ring added again to vanilla Uniques since its optional to turn it in for a quest. Layout of Perks tab changed to be more convenient. Conditional formatting fixed across the whole spreadsheet. Y/N changed to checkboxes on every tab except Quest because it needs to be redone anyway. Books type column fixed, skill books and spell tomes style changed for better sorting About 25 empty descriptions filled in in Books tab. Multiple link errors fixed and all of them are verified plus consistent now on all tabs except quests
B10: 44430 | C10: Removed Enchanted ring from vanilla Uniques - quest item Removed Chrysamere from vanilla Uniques - CC content Removed Tandil's Staff from vanilla Uniques - quest item Zephyr and Talor Dreth's robes are moved to Dawnguard Uniques Mutually exclusive items are now marked Added following list of vanilla uniques: https://pastebin.com/PZKAsnFa Added following Dawnguard uniques: Akaviri Sword Staff of Ruunvald Vampire Royal Armor Bone Hawk Ring Bone Hawk Amulet Added following Dragonborn uniques: Ancient Nordic Pickaxe Unique Gear tab added to Dashboard
B11: 44429 | C11: Added 5 paragons to Collectables tab Added following list of misc collectables : https://pastebin.com/WPE38dbh Collectables tab added to Dashboard
B12: 44426 | C12: Fixed some minor formatting issues Fixed spell location column Added missing tome ids for DLC spells
B13: 44423 | C13: Civil war locations are separated from the main list All fast travel markers verified Location added: The Chill Skuldafn Minor style and error fixes Formulas for locations tab replaced. Locations and Merchants tabs added to dashboard. Added "List" column to the Books tab with link to an explanation
B14: 44421 | C14: Removed duplicate book: Diary of Faire Agarwen Removed unobtainable books: Gallus's Journal The Secrets of Ragnvald Tolfdir's Book Unsent Afflicted Letter Added 3 Elder Scrolls as quest books Following list of books moved to quest books: https://pastebin.com/RwnZMCNK Fixed links to DG spell tomes Fixed style on books tab Removed Jarrin root from alchemy ingridients due to it being unique quest item. Added following spells: Summon Unbound Dremora Arniel Convection Summon Arniel's Shade Added prototype of the Dashboard tab with optional tracking. Requires testing and fixing other tabs to be fully complete
B15: 44410 | C15: Fixed incorrect spell levels Added missing spell Vision of the Tenth eye Added missing location East Empire company Warehouse Added 7 missing unique items. Theres probably more I didn't catch Added missing book Children of the All Maker Removed duplicate book The "Madmen" of the Reach Added a hidden quest Archery Practice given by Angi in outside Falkreath
A16: 0.5 | B16: 44283 | C16: Added missing Dragonborn and Dawngaurd books Marked some book which must be turned in for quests
B17: 44272 | C17: Added numbering to spell levels to make sorting easier Marked spells that all races start with as already collected Added missing location quest for Lair's retreat Fixed a few typos and some cleanup on quest tab Moved a couple quests to the correct location
B18: 44226 | C18: Fixed some typos, errors in book count formulas, and 1 missing book, slight formatting changes
A19: 0.4 | B19: 44095 | C19: Finished adding all missing DLC spells and spell tomes
B20: 43982 | C20: Finished adding links to Quest tab
B21: 43971 | C21: Corrected two locations which are not on the map Added Hunter's rest and Raven Rock Mine to locations
B22: 43959 | C22: Added missing Nightingale armor pieces to Unique Gear
B23: 43953 | C23: Added missing unique item Staff of Jerik Gaudurson Added some items to gather to the lists in quest tab Fixed conditional formatting on quests tab
B24: 43949 | C24: Added links to: spells tab, followers tab, shouts tab, alchemy ingrediants tab, merchants tab Removed two duplicate Unique items
A25: 0.3 | B25: 43947 | C25: Added spell tomes and links to Books sheet Fixed error in read books formula More edits for consistancy Added formula and conditional formatting for total thieves guild jobs.
B26: 43945 | C26: Added two missing Inns to the list of locations Fixed some slight errors in formulas
A27: 0.2 | B27: 43934 | C27: Made a few modifications for consistancy Added Merchants tab
A28: 0.1 | B28: 43369 | C28: First Release | D28: =HYPERLINK("https://docs.google.com/spreadsheets/d/1yHg39nzekiEgwuG07YFAhSequQBaKBT-6ArOAbQaOT4/edit?usp=sharing","link to original version (mostly here for crediting the original work)") -> link to original version (mostly here for crediting the original work)

Sheet TodoFeedback
A1: Completion Percentage | B1: Task Name
A2: Key (rough estmates): 0-10% = Not started/outlined only 11-90%= In progress 91-99%= Almost done; Needs final checks 100%= Complete
B3: Comments are open to everyone please suggest changes! Please put comments in the appropriate spot. On the specific item in the to do list if it relates to the page as a whole or the spot in the page itself that has a problem. I can only have one active comment thread per cell If one already exists just add to the thread.
B4: DO NOT close or open a comment that is not your own. I need those to fix issues and I will close them as needed.
B5: Comment on this cell with any NEW suggestions for features or fixes
B6: Comment on this cell for general discussion, feedback, questions on checklist
A7: 1 | B7: Add Dawnguard and Dragonborn Spells and Spell tomes
A8: 1 | B8: Add Dawnguard and Dragonborn Books
A9: 1 | B9: Add Dawnguard and Dragonborn ingredients and effects
A10: 1 | B10: Add a column for which leveled list each book is in to aid in finding them
A11: 1 | B11: Verify all fast-travel locations and check for duplicates
A12: 1 | B12: Verify that all recruitable followers are in the list and that they are properly marked
A13: 1 | B13: Find quest-related books which must be turned in and remove them from Books list
A14: 1 | B14: Add more data to the recruitable followers list (gender, race, etc.)
A15: 1 | B15: Fix spell locations column. I didn't make it I have no idea what all those letters mean.
A16: 1 | B16: Add more collectables to collectables tab. Only unique items that are not equippable should go here.
A17: 1 | B17: Verify all unique gear is in the list and remove any quest-specific items that must be turned in to complete the quest
A18: 1 | B18: Add werewolf and vampire perks to Perks tab
... A36: 0 | B36: Add a list of notes (probably not happening)

Sheet Dashboard
A1: Tab name | B1: Track | C1: Progress bar | G1: Completed % | H1: Left % | I1: Multiplier
A2: Total progression | B2: Y | C2: =IFERROR(__xludf.DUMMYFUNCTION("IF(B2=""Y"",SPARKLINE(G2:H2,{""charttype"",""bar"";""max"",1;""min"",0;""color1"",""#b7e1cd"";""color2"",""#f4c7c3""}),""Not tracked"")"),"") | G2: =round(SUMPRODUCT(G3:G14,I3:I14)/COUNTIF(I3:I14,"=1"),4) -> 0.001 | H2: =100%-G2 -> 0.999 | I2: =if(B2="Y",1,0) -> 1
A3: Quests | B3: Y | C3: =IFERROR(__xludf.DUMMYFUNCTION("IF(B3=""Y"",SPARKLINE(G3:H3,{""charttype"",""bar"";""max"",1;""min"",0;""color1"",""#b7e1cd"";""color2"",""#f4c7c3""}),""Not tracked"")"),"") | G3: =Quests!I1 -> 0 | H3: =100%-G3 -> 1 | I3: =if(B3="Y",1,0) -> 1
A4: Enchanting Effects | B4: Y | C4: =IFERROR(__xludf.DUMMYFUNCTION("IF(B4=""Y"",SPARKLINE(G4:H4,{""charttype"",""bar"";""max"",1;""min"",0;""color1"",""#b7e1cd"";""color2"",""#f4c7c3""}),""Not tracked"")"),"") | G4: ='Enchanting Effects'!B2 -> 0 | H4: =100%-G4 -> 1 | I4: =if(B4="Y",1,0) -> 1
A5: Spells | B5: Y | C5: =IFERROR(__xludf.DUMMYFUNCTION("IF(B5=""Y"",SPARKLINE(G5:H5,{""charttype"",""bar"";""max"",1;""min"",0;""color1"",""#b7e1cd"";""color2"",""#f4c7c3""}),""Not tracked"")"),"") | G5: =Spells!B2 -> 0.011976048 | H5: =100%-G5 -> 0.98802395 | I5: =if(B5="Y",1,0) -> 1
A6: Dragon Shouts | B6: Y | C6: =IFERROR(__xludf.DUMMYFUNCTION("IF(B6=""Y"",SPARKLINE(G6:H6,{""charttype"",""bar"";""max"",1;""min"",0;""color1"",""#b7e1cd"";""color2"",""#f4c7c3""}),""Not tracked"")"),"") | G6: ='Dragon Shouts'!A2 -> 0 | H6: =100%-G6 -> 1 | I6: =if(B6="Y",1,0) -> 1
A7: Locations | B7: Y | C7: =IFERROR(__xludf.DUMMYFUNCTION("IF(B7=""Y"",SPARKLINE(G7:H7,{""charttype"",""bar"";""max"",1;""min"",0;""color1"",""#b7e1cd"";""color2"",""#f4c7c3""}),""Not tracked"")"),"") | G7: =Locations!G4 -> 0 | H7: =100%-G7 -> 1 | I7: =if(B7="Y",1,0) -> 1
A8: Merchants Invested | B8: Y | C8: =IFERROR(__xludf.DUMMYFUNCTION("IF(B8=""Y"",SPARKLINE(G8:H8,{""charttype"",""bar"";""max"",1;""min"",0;""color1"",""#b7e1cd"";""color2"",""#f4c7c3""}),""Not tracked"")"),"") | G8: =Merchants!C3 -> 0 | H8: =100%-G8 -> 1 | I8: =if(B8="Y",1,0) -> 1
A9: Unique Gear | B9: Y | C9: =IFERROR(__xludf.DUMMYFUNCTION("IF(B9=""Y"",SPARKLINE(G9:H9,{""charttype"",""bar"";""max"",1;""min"",0;""color1"",""#b7e1cd"";""color2"",""#f4c7c3""}),""Not tracked"")"),"") | G9: =('Unique Gear'!D6 + 'Unique Gear'!D186 + 'Unique Gear'!D216)/3 -> 0 | H9: =100%-G9 -> 1 | I9: =if(B9="Y",1,0) -> 1
A10: Collectible Items | B10: Y | C10: =IFERROR(__xludf.DUMMYFUNCTION("IF(B10=""Y"",SPARKLINE(G10:H10,{""charttype"",""bar"";""max"",1;""min"",0;""color1"",""#b7e1cd"";""color2"",""#f4c7c3""}),""Not tracked"")"),"") | G10: ='Collectible Items'!A31 -> 0 | H10: =100%-G10 -> 1 | I10: =if(B10="Y",1,0) -> 1
A11: Books | B11: Y | C11: =IFERROR(__xludf.DUMMYFUNCTION("IF(B11=""Y"",SPARKLINE(G11:H11,{""charttype"",""bar"";""max"",1;""min"",0;""color1"",""#b7e1cd"";""color2"",""#f4c7c3""}),""Not tracked"")"),"") | G11: =(Books!G3 + Books!K3 + Books!M3 + Books!K601)/400 -> 0 | H11: =100%-G11 -> 1 | I11: =if(B11="Y",1,0) -> 1
A12: Recruitable Followers | B12: Y | C12: =IFERROR(__xludf.DUMMYFUNCTION("IF(B12=""Y"",SPARKLINE(G12:H12,{""charttype"",""bar"";""max"",1;""min"",0;""color1"",""#b7e1cd"";""color2"",""#f4c7c3""}),""Not tracked"")"),"") | G12: ='Recruitable Followers'!B2 -> 0 | H12: =100%-G12 -> 1 | I12: =if(B12="Y",1,0) -> 1
A13: Learned Alchemy Effects | B13: Y | C13: =IFERROR(__xludf.DUMMYFUNCTION("IF(B13=""Y"",SPARKLINE(G13:H13,{""charttype"",""bar"";""max"",1;""min"",0;""color1"",""#b7e1cd"";""color2"",""#f4c7c3""}),""Not tracked"")"),"") | G13: ='Learned Alchemy Effects'!A2 -> 0 | H13: =100%-G13 -> 1 | I13: =if(B13="Y",1,0) -> 1
A14: Perks | B14: Y | C14: =IFERROR(__xludf.DUMMYFUNCTION("IF(B14=""Y"",SPARKLINE(G14:H14,{""charttype"",""bar"";""max"",1;""min"",0;""color1"",""#b7e1cd"";""color2"",""#f4c7c3""}),""Not tracked"")"),"") | G14: =Perks!M4 -> 0 | H14: =100%-G14 -> 1 | I14: =if(B14="Y",1,0) -> 1

Sheet Credits
A1: Name | B1: Author | C1: Contributions
A2: Current Document | B2: Xboxiscrunchy | C2: Main author. Mostly formatting work honestly.
B3: Mezotaken | C3: Reformatting and many additions
A4: Skyrim 100% Completion Checklist v0.6 | B4: TheDJjams | C4: Quests tab formulas and creation club content
A5: Skyrim AE 100% Completion Checklist (v0.5) - AleHitti Version | B5: Alejandro Hitti | C5: Most of the creation club additions except the quests tab, Redoing Alchemy Tab
A6: IP - Skyrim AE 100% Completion Checklist (v0.5) - AshCamo Personal Edit | B6: Ashley Motter | C6: Most of the creation club additions except the quests tab
B7: Chasingcalliope | C7: Reformatted the books tab.
A8: Skyrim 100% Checklist (v0.01) | B8: bastionf***s | C8: Everything below was compiled here by bastionfucks
A9: =HYPERLINK("https://www.nexusmods.com/skyrim/mods/23188/?tab=images","Skyrim Books Checklist") -> Skyrim Books Checklist | B9: roachy1 | C9: The Books tab is based off of roachy1's work and the UESP wiki.
A10: =HYPERLINK("https://www.reddit.com/r/skyrim/comments/50d750/skyrim_character_planning_spreadsheet/","Skyrim Character Planning Spreadsheet") -> Skyrim Character Planning Spreadsheet | B10: porter2613 | C10: The Perks tab is based off of porter2613's work.
A11: =HYPERLINK("https://www.reddit.com/r/skyrim/comments/2r8nvw/all_skyrim_spells_broken_down_by_level_and_school/","All Skyrim Spells broken down by Level and School") -> All Skyrim Spells broken down by Level and School | B11: alanchavez | C11: The spells tab is a copy of alanchavez's work
A12: =HYPERLINK("https://www.nexusmods.com/skyrim/mods/51284/?tab=1&navtag=http%3A%2F%2Fwww.nexusmods.com%2Fskyrim%2Fajax%2Fmoddescription%2F%3Fid%3D51284%26preview%3D&pUp=1","Skyrim Quest Checklists and Quest Mod Checklists") -> Skyrim Quest Checklists and Quest Mod Checklists | B12: Sakr3d | C12: The Quests, Collectible Items, and Dragon Shout tabs are based off of Sakr3d's work.
A13: =HYPERLINK("https://www.reddit.com/r/skyrim/comments/mmtdf/filterable_list_of_alchemy_ingredients/","Filterable list of alchemy ingredients") -> Filterable list of alchemy ingredients | B13: u/Guysmiley777 | C13: The Alchemy tabis based of off Guysmiley777's wor.
A14: =HYPERLINK("https://en.uesp.net/wiki/Main_Page","The UESP Wiki") -> The UESP Wiki | B14: All Authors | C14: The UESP wiki was the best resource and I am forever in your debt.
A15: Bastionfucks built the orininal spreadsheet based on the work of the spreadsheets that other people made. I have added to his work by refining the spreadsheet and adding edits for consistency and some missing info
A16: =HYPERLINK("https://creativecommons.org/licenses/by/4.0/","This work is licensed under a Creative Commons Attribution 4.0 International License.") -> This work is licensed under a Creative Commons Attribution 4.0 International License.

Sheet Quests
A1: Y | B1: Anniversary Edition? | C1: S K Y R I M Q U E S T C H E C K L I S T | I1: =if(A1="Y", (average(I4,I27,D46,I46,D54,I75,I98,I132,I153,I178,I183,I214,I242,I257,I274,I300,I329,I360,I386,I400,I410,I441,I471,I519)),average(I4,I27,D46,I46,D54,I75,I98,I132,I153,I178,I183,I214,I242,I257,I274,I300,I329,I360,I386,I400,I410,I441,I471)) -> 0
A2: Side quests highlighted in orange. Level dependent quests highlighted in green. | H2: last updated: 2023.07.14
B3: Quest | D3: Description | I3: Giver
A4: Main Quest | I4: =(countif(A5:A23,"Y")/19) -> 0
A5: N | B5: =hyperlink("https://en.uesp.net/wiki/Skyrim:Unbound", "Unbound") -> Unbound | D5: Escape Imperial custody and a dragon raid. | I5: N/A
A6: N | B6: =hyperlink("https://en.uesp.net/wiki/Skyrim:Before_the_Storm", "Before the Storm") -> Before the Storm | D6: Inform the Jarl of Whiterun about the dragon attack on Helgen. | I6: Hadvar or Ralof
A7: N | B7: =hyperlink("https://en.uesp.net/wiki/Skyrim:Bleak_Falls_Barrow_(quest)", "Bleak Falls Barrow") -> Bleak Falls Barrow | D7: Retrieve the Dragonstone. | I7: Jarl Balgruuf
A8: N | B8: =hyperlink("https://en.uesp.net/wiki/Skyrim:Dragon_Rising", "Dragon Rising") -> Dragon Rising | D8: Investigate a Dragon sighting near Whiterun. | I8: Jarl Balgruuf
A9: N | B9: =hyperlink("https://en.uesp.net/wiki/Skyrim:The_Way_of_the_Voice", "The Way of the Voice") -> The Way of the Voice | D9: Meet the Greybeards. | I9: Jarl Balgruuf
A10: N | B10: =hyperlink("https://en.uesp.net/wiki/Skyrim:The_Horn_of_Jurgen_Windcaller", "The Horn of Jurgen Windcaller") -> The Horn of Jurgen Windcaller | D10: Retrieve a Greybeard artifact from Ustengrav. | I10: Arngeir
A11: N | B11: =hyperlink("https://en.uesp.net/wiki/Skyrim:A_Blade_in_the_Dark", "A Blade in the Dark") -> A Blade in the Dark | D11: Prove you are Dragonborn to Delphine by slaying the dragon Sahloknir. | I11: A Mysterious Note
A12: N | B12: =hyperlink("https://en.uesp.net/wiki/Skyrim:Diplomatic_Immunity", "Diplomatic Immunity") -> Diplomatic Immunity | D12: Infiltrate a party at the Thalmor Embassy. | I12: Delphine
A13: N | B13: =hyperlink("https://en.uesp.net/wiki/Skyrim:A_Cornered_Rat", "A Cornered Rat") -> A Cornered Rat | D13: Locate Esbern. | I13: Delphine
A14: N | B14: =hyperlink("https://en.uesp.net/wiki/Skyrim:Alduin's_Wall", "Alduin's Wall") -> Alduin's Wall | D14: Locate the prophecy within Sky Haven Temple. | I14: Esbern
A15: N | B15: =hyperlink("https://en.uesp.net/wiki/Skyrim:The_Throat_of_the_World", "The Throat of the World") -> The Throat of the World | D15: Receive a lesson from Paarthurnax. | I15: Arngeir
A16: N | B16: =hyperlink("https://en.uesp.net/wiki/Skyrim:Elder_Knowledge", "Elder Knowledge") -> Elder Knowledge | D16: Locate an Elder Scroll. | I16: Paarthurnax
A17: N | B17: =hyperlink("https://en.uesp.net/wiki/Skyrim:Alduin's_Bane", "Alduin's Bane") -> Alduin's Bane | D17: Exploit the Time Wound to learn Dragonrend. | I17: Paarthurnax
A18: N | B18: =hyperlink("https://en.uesp.net/wiki/Skyrim:The_Fallen", "The Fallen") -> The Fallen | D18: Capture and interrogate one of Alduin's allies. | I18: Paarthurnax Arngeir Esbern
A19: N | B19: =hyperlink("https://en.uesp.net/wiki/Skyrim:Paarthurnax_(quest)", "Paarthurnax (optional)") -> Paarthurnax (optional) | D19: Deal with a potential threat.
A20: N | B20: =hyperlink("https://en.uesp.net/wiki/Skyrim:Season_Unending", "Season Unending (optional)") -> Season Unending (optional) | D20: Enforce a ceasefire to secure Dragonsreach.
A21: N | B21: =hyperlink("https://en.uesp.net/wiki/Skyrim:The_World-Eater's_Eyrie", "The World-Eater's Eyrie") -> The World-Eater's Eyrie | D21: Battle through Skuldafn Temple to reach Alduin's portal to Sovngarde.
A22: N | B22: =hyperlink("https://en.uesp.net/wiki/Skyrim:Sovngarde_(quest)", "Sovngarde") -> Sovngarde | D22: Seek out Alduin within Sovngarde.
A23: N | B23: =hyperlink("https://en.uesp.net/wiki/Skyrim:Dragonslayer", "Dragonslayer") -> Dragonslayer | D23: Put an end to the World Eater.
A25: Faction Quests
A27: College of Winterhold | I27: =((countif(A29:A44,"Y")+countif(F29:F44,"Y"))/25) -> 0
A28: Main Quests | F28: Radiant Quests
A29: N | B29: =hyperlink("https://en.uesp.net/wiki/Skyrim:College_Objective_Quest", "College Objective Quest") -> College Objective Quest | C29: Visit the College of Winterhold. | F29: N | G29: =hyperlink("https://en.uesp.net/wiki/Skyrim:Enchanting_Pick-Up", "Enchanting Pick-Up") -> Enchanting Pick-Up | H29: Sergius wants you to pick-up an item from a client for enchanting. | I29: Sergius Turrianus
A30: N | B30: =hyperlink("https://en.uesp.net/wiki/Skyrim:First_Lessons", "First Lessons") -> First Lessons | C30: Join the College of Winterhold. | F30: N | G30: =hyperlink("https://en.uesp.net/wiki/Skyrim:Restocking_Soul_Gems", "Restocking Soul Gems") -> Restocking Soul Gems | H30: Help Sergius Turrianus to fill his stock with soul gems. | I30: Sergius Turrianus
A31: N | B31: =hyperlink("https://en.uesp.net/wiki/Skyrim:Under_Saarthal", "Under Saarthal") -> Under Saarthal | C31: Uncover the mysteries beneath this ancient ruin. | D31: Tolfdir | F31: N | G31: =hyperlink("https://en.uesp.net/wiki/Skyrim:Tolfdir_The_Absent-Minded", "Tolfdir The Absent-Minded") -> Tolfdir The Absent-Minded | H31: Help Tolfdir find his missing alembic. | I31: Tolfdir
A32: N | B32: =hyperlink("https://en.uesp.net/wiki/Skyrim:Hitting_the_Books", "Hitting the Books") -> Hitting the Books | C32: Find the books needed to identify the artifact found in Saarthal. | D32: Savos Aren | F32: N | G32: =hyperlink("https://en.uesp.net/wiki/Skyrim:Aftershock", "Aftershock") -> Aftershock | H32: Put an end to the rupture caused by the Eye of Magnus. | I32: Tolfdir
A33: N | B33: =hyperlink("https://en.uesp.net/wiki/Skyrim:Good_Intentions", "Good Intentions") -> Good Intentions | C33: Find and consult the Augur of Dunlain. | D33: Tolfdir | F33: N | G33: =hyperlink("https://en.uesp.net/wiki/Skyrim:Fetch_me_that_Book!", "Fetch me that Book!") -> Fetch me that Book! | H33: Fetch a book for Urag gro-Shub. | I33: Urag gro-Shub
A34: N | B34: =hyperlink("https://en.uesp.net/wiki/Skyrim:Revealing_the_Unseen", "Revealing the Unseen") -> Revealing the Unseen | C34: Discover the location of Magnus' staff. | D34: Mirabelle Ervine | F34: N | G34: =hyperlink("https://en.uesp.net/wiki/Skyrim:Shalidor's_Insights", "Shalidor's Insights") -> Shalidor's Insights | H34: Discover the writings of Shalidor and benefit from his wisdom. | I34: Urag gro-Shub
A35: N | B35: =hyperlink("https://en.uesp.net/wiki/Skyrim:Containment", "Containment") -> Containment | C35: Deal with the aftermath of the Eye's power surge. | F35: Master Skill Quests
A36: N | B36: =hyperlink("https://en.uesp.net/wiki/Skyrim:The_Staff_of_Magnus", "The Staff of Magnus") -> The Staff of Magnus | C36: Retrieve the Staff of Magnus. | D36: Mirabelle Ervine | F36: N | G36: =hyperlink("https://en.uesp.net/wiki/Skyrim:Alteration_Ritual_Spell", "Alteration Ritual Spell") -> Alteration Ritual Spell | H36: Find the Fang and use it to get Heartscales from a dragon. | I36: Tolfdir
A37: N | B37: =hyperlink("https://en.uesp.net/wiki/Skyrim:The_Eye_of_Magnus", "The Eye of Magnus") -> The Eye of Magnus | C37: Reclaim the College and contain the Eye. | F37: N | G37: =hyperlink("https://en.uesp.net/wiki/Skyrim:Conjuration_Ritual_Spell", "Conjuration Ritual Spell") -> Conjuration Ritual Spell | H37: Find a Sigil Stone by summoning a Daedra. | I37: Phinis Gestor
A38: Optional Quests | F38: N | G38: =hyperlink("https://en.uesp.net/wiki/Skyrim:Destruction_Ritual_Spell", "Destruction Ritual Spell") -> Destruction Ritual Spell | H38: Learn the most powerful Destruction spells in Skyrim. | I38: Faralda
A39: N | B39: =hyperlink("https://en.uesp.net/wiki/Skyrim:Arniel's_Endeavor", "Arniel's Endeavor") -> Arniel's Endeavor | C39: Uncover an ancient Dwemer secret. | D39: Arniel Gane | F39: N | G39: =hyperlink("https://en.uesp.net/wiki/Skyrim:Illusion_Ritual_Spell", "Illusion Ritual Spell") -> Illusion Ritual Spell | H39: Find some books about Illusion Magic to learn Master Spells. | I39: Drevis Neloren
A40: N | B40: =hyperlink("https://en.uesp.net/wiki/Skyrim:Brelyna's_Practice", "Brelyna's Practice") -> Brelyna's Practice | C40: Help Brelyna Maryon test spells. | D40: Brelyna Maryon | F40: N | G40: =hyperlink("https://en.uesp.net/wiki/Skyrim:Restoration_Ritual_Spell", "Restoration Ritual Spell") -> Restoration Ritual Spell | H40: Find the Augur of Dunlain and learn more about Restoration Magic. | I40: Colette Marence
A41: N | B41: =hyperlink("https://en.uesp.net/wiki/Skyrim:J'zargo's_Experiment", "J'zargo's Experiment") -> J'zargo's Experiment | C41: Help J'zargo test out a fiery new spell. | D41: J'zargo
A42: N | B42: =hyperlink("https://en.uesp.net/wiki/Skyrim:Onmund's_Request", "Onmund's Request") -> Onmund's Request | C42: Help Onmund negotiate the return of a family amulet. | D42: Onmund
...

Sheet Enchanting Effects
A1: Enchantment Name | B1: Obtained? | C1: Weapon | D1: Head | E1: Neck | F1: Chest | G1: Hands | H1: Finger | I1: Feet | J1: Shield | K1: School | L1: Base Magnitude | M1: Base Cost | N1: Disenchant
A2: - | B2: =(countif(B3:B60,"*Y*")/COUNTA(B3:B60)) -> 0 | C2: - | D2: - | E2: - | F2: - | G2: - | H2: - | I2: - | J2: - | K2: - | L2: - | M2: - | N2: -
A3: =HYPERLINK("https://en.uesp.net/wiki/Skyrim:Fortify_Alchemy","Fortify Alchemy") -> Fortify Alchemy | B3: N | C3: - | D3: X | E3: X | F3: - | G3: X | H3: X | I3: - | J3: - | K3: - | L3: Plus 8% potion strength | M3: 167 | N3: Bracers/Gauntlets and Helmets "of Alchemy" Muiri's Ring Ring of Pure Mixtures Dwarven Helment of Eminent Alteration
A4: =HYPERLINK("https://en.uesp.net/wiki/Skyrim:Fortify_Alteration","Fortify Alteration") -> Fortify Alteration | B4: N | C4: - | D4: X | E4: X | F4: X | G4: - | H4: X | I4: - | J4: - | K4: - | L4: Minus 8% casting cost | M4: 206 | N4: Armor, Bracers, and Helmets "of Alteration"
A5: =HYPERLINK("https://en.uesp.net/wiki/Skyrim:Enchanting_Effects","Fortify Alteration & Magicka Regen") -> Fortify Alteration & Magicka Regen | B5: N | C5: - | D5: - | E5: - | F5: X | G5: - | H5: - | I5: - | J5: - | K5: - | L5: Negative 5% casting cost Plus 10% Magicka Regen | M5: 176 | N5: Robes "of Alteration"
A6: =HYPERLINK("https://en.uesp.net/wiki/Skyrim:Fortify_Archery","Fortify Archery") -> Fortify Archery | B6: N | C6: - | D6: X | E6: X | F6: - | G6: X | H6: X | I6: - | J6: - | K6: - | L6: Plus 13% damage | M6: 352 | N6: Bracers/Gauntlets, Circlets, Helmets, and Rings "of Archery"
A7: =HYPERLINK("https://en.uesp.net/wiki/Skyrim:Fortify_Barter","Fortify Barter") -> Fortify Barter | B7: N | C7: - | D7: - | E7: X | F7: - | G7: - | H7: - | I7: - | J7: - | K7: - | L7: Prices Improved by 8% | M7: 206 | N7: Necklaces "of Haggling"
A8: =HYPERLINK("https://en.uesp.net/wiki/Skyrim:Fortify_Block","Fortify Block") -> Fortify Block | B8: N | C8: - | D8: - | E8: X | F8: - | G8: X | H8: X | I8: - | J8: X | K8: - | L8: Plus 13% damage blocked | M8: 235 | N8: Shields "of Blocking"
A9: =HYPERLINK("https://en.uesp.net/wiki/Skyrim:Fortify_Carry_Weight","Fortify Carry Weight") -> Fortify Carry Weight | B9: N | C9: - | D9: - | E9: X | F9: - | G9: X | H9: - | I9: X | J9: - | K9: - | L9: Plus 15 | M9: 393 | N9: Charmed Necklace Boots "of Brawn" Boots "of Hauling" Boots "of Lifting" Boots "of the Mammoth" Boots "of the Ox" Boots "of Strength"
A10: =HYPERLINK("https://en.uesp.net/wiki/Skyrim:Fortify_Conjuration","Fortify Conjuration") -> Fortify Conjuration | B10: N | C10: - | D10: X | E10: X | F10: X | G10: - | H10: X | I10: - | J10: - | K10: - | L10: Minus 8% casting cost | M10: 248 | N10: Armor, Bracers, and Helmet "of Conjuring" Circlets, and Imperial Helmets "of Conjuration"
A11: =HYPERLINK("https://en.uesp.net/wiki/Skyrim:Enchanting_Effects","Fortify Conjuration & Magicka Regen") -> Fortify Conjuration & Magicka Regen | B11: N | C11: - | D11: - | E11: - | F11: X | G11: - | H11: - | I11: - | J11: - | K11: - | L11: Negative 5% casting cost Plus 10% Magicka Regen | M11: 199 | N11: Robes and Vampire Armor "of Conjuration"
A12: =HYPERLINK("https://en.uesp.net/wiki/Skyrim:Fortify_Destruction","Fortify Destruction") -> Fortify Destruction | B12: N | C12: - | D12: X | E12: X | F12: X | G12: - | H12: X | I12: - | J12: - | K12: - | L12: Minus 8% casting cost | M12: 256 | N12: Armor, Bracers, Circlets, Helmets, Necklaces, and Rings "of Destruction" Thalmor Robes, Hooded Thalmor Robes
A13: =HYPERLINK("https://en.uesp.net/wiki/Skyrim:Enchanting_Effects","Fortify Destruction & Magicka Regen") -> Fortify Destruction & Magicka Regen | B13: N | C13: - | D13: - | E13: - | F13: X | G13: - | H13: - | I13: - | J13: - | K13: - | L13: Negative 5% casting cost Plus 10% Magicka Regen | M13: 205 | N13: Robes and Vampire Armor "of Destruction"
A14: =HYPERLINK("https://en.uesp.net/wiki/Skyrim:Regenerate_Health","Fortify Healing Rate") -> Fortify Healing Rate | B14: N | C14: - | D14: - | E14: X | F14: X | G14: - | H14: X | I14: - | J14: - | K14: - | L14: Plus 10% | M14: 251 | N14: Armor, Necklaces, and Rings "of Mending" Armor, Necklaces, and Rings "of Revival" Armor, Necklaces, and Rings "of Regeneration" Armor, Necklaces, and Rings "of Remedy"
A15: =HYPERLINK("https://en.uesp.net/wiki/Skyrim:Fortify_Health","Fortify Health") -> Fortify Health | B15: N | C15: - | D15: - | E15: X | F15: X | G15: - | H15: X | I15: - | J15: X | K15: - | L15: Plus 20 | M15: 202 | N15: Armor "of Health" Enchanted Ring
A16: =HYPERLINK("https://en.uesp.net/wiki/Skyrim:Fortify_Heavy_Armor","Fortify Heavy Armor") -> Fortify Heavy Armor | B16: N | C16: - | D16: - | E16: X | F16: X | G16: X | H16: X | I16: - | J16: - | K16: - | L16: Plus 8 Skill | M16: 157 | N16: Armor and Necklaces "of the Knight"
A17: =HYPERLINK("https://en.uesp.net/wiki/Skyrim:Fortify_Illusion","Fortify Illusion") -> Fortify Illusion | B17: N | C17: - | D17: X | E17: X | F17: X | G17: - | H17: X | I17: - | J17: - | K17: - | L17: Minus 8% casting cost | M17: 226 | N17: Armor, and Helmets "of Illusion"
A18: =HYPERLINK("https://en.uesp.net/wiki/Skyrim:Enchanting_Effects","Fortify Illusion & Magicka Regen") -> Fortify Illusion & Magicka Regen | B18: N | C18: - | D18: - | E18: - | F18: X | G18: - | H18: - | I18: - | J18: - | K18: - | L18: Negative 5% casting cost Plus 10% Magicka Regen | M18: 182 | N18: Robes "of Illusion"
A19: =HYPERLINK("https://en.uesp.net/wiki/Skyrim:Fortify_Light_Armor","Fortify Light Armor") -> Fortify Light Armor | B19: N | C19: - | D19: - | E19: X | F19: X | G19: X | H19: X | I19: - | J19: - | K19: - | L19: Plus 8 Skill | M19: 137 | N19: Armor and Necklaces "of the Squire"
A20: =HYPERLINK("https://en.uesp.net/wiki/Skyrim:Fortify_Lockpicking","Fortify Lockpicking") -> Fortify Lockpicking | B20: N | C20: - | D20: X | E20: X | F20: - | G20: X | H20: X | I20: - | J20: - | K20: - | L20: Plus 13% | M20: 168 | N20: Bracers/Gauntlets and Necklaces "of Lockpicking"
A21: =HYPERLINK("https://en.uesp.net/wiki/Skyrim:Fortify_Magicka","Fortify Magicka") -> Fortify Magicka | B21: N | C21: - | D21: X | E21: X | F21: - | G21: X | H21: X | I21: - | J21: - | K21: - | L21: Plus 20 | M21: 188 | N21: Circlets, Helmets, and Rings "of Magicka" Adept Hood Amulet of Julianos Apprentice Hood Black Mage Hood Executioner's Hood Mage's Circlet Novice Hood Savos Aren's Amulet
A22: =HYPERLINK("https://en.uesp.net/wiki/Skyrim:Regenerate_Magicka","Fortify Magicka Regen") -> Fortify Magicka Regen | B22: N | C22: - | D22: X | E22: - | F22: X | G22: - | H22: X | I22: - | J22: - | K22: - | L22: Plus 20% | M22: 53 | N22: Helmets, Rings, and Robes "of Recovery" Armor, Helmets, Rings, and Robes "of Replenishing" Helmets, Rings, and Robes "of Resurgence" Adept Robes Apprentice Robes Black Mage Robes Blue Mage Robes Expert Robes Hooded Black Mage Robes Hooded Necromancer Robes Master Robes Mythic Dawn Robes Necromancer Robes Novice Robes
A23: =HYPERLINK("https://en.uesp.net/wiki/Skyrim:Fortify_One-handed","Fortify One-Handed") -> Fortify One-Handed | B23: N | C23: - | D23: - | E23: X | F23: - | G23: X | H23: X | I23: X | J23: - | K23: - | L23: Plus 13% damage | M23: 369 | N23: Bracers/Gauntlets, Necklaces, and Rings "of Wielding"
A24: =HYPERLINK("https://en.uesp.net/wiki/Skyrim:Fortify_Pickpocket","Fortify Pickpocket") -> Fortify Pickpocket | B24: N | C24: - | D24: - | E24: X | F24: - | G24: X | H24: X | I24: X | J24: - | K24: - | L24: Plus 13% mulitplier to success chance | M24: 184 | N24: Bracers/Gauntlets and Rings "of Deft Hands"
A25: =HYPERLINK("https://en.uesp.net/wiki/Skyrim:Fortify_Restoration","Fortify Restoration") -> Fortify Restoration | B25: N | C25: - | D25: X | E25: X | F25: X | G25: - | H25: X | I25: - | J25: - | K25: - | L25: Minus 8% casting cost | M25: 231 | N25: Armor, Circlets, Helmets, and Rings "of Restoration"
A26: =HYPERLINK("https://en.uesp.net/wiki/Skyrim:Enchanting_Effects","Fortify Restoration & Magicka Regen") -> Fortify Restoration & Magicka Regen | B26: N | C26: - | D26: - | E26: - | F26: X | G26: - | H26: - | I26: - | J26: - | K26: - | L26: Negative 5% casting cost Plus 10% Magicka Regen | M26: 193 | N26: Robes "of Restoration"
A27: =HYPERLINK("https://en.uesp.net/wiki/Skyrim:Fortify_Smithing","Fortify Smithing") -> Fortify Smithing | B27: N | C27: - | D27: - | E27: X | F27: X | G27: X | H27: X | I27: - | J27: - | K27: - | L27: Plus 8% tempering strength | M27: 236 | N27: Bracers/Gauntlet, Necklaces, and rings "of Smithing" Silver-Blood Family Ring The Forgemaster's Fingers
A28: =HYPERLINK("https://en.uesp.net/wiki/Skyrim:Fortify_Sneak","Fortify Sneak") -> Fortify Sneak | B28: N | C28: - | D28: - | E28: X | F28: - | G28: X | H28: X | I28: X | J28: - | K28: - | L28: Plus 13% | M28: 672 | N28: Boots, Necklaces, and Rings "of Sneaking"
A29: =HYPERLINK("https://en.uesp.net/wiki/Skyrim:Fortify_Stamina","Fortify Stamina") -> Fortify Stamina | B29: N | C29: - | D29: - | E29: X | F29: X | G29: - | H29: X | I29: X | J29: - | K29: - | L29: Plus 20 | M29: 161 | N29: Armor, Boots, Necklaces, and Rings "of Stamina"
A30: =HYPERLINK("https://en.uesp.net/wiki/Skyrim:Regenerate_Stamina","Fortify Stamina Regen") -> Fortify Stamina Regen | B30: N | C30: - | D30: - | E30: X | F30: X | G30: - | H30: X | I30: X | J30: - | K30: - | L30: Plus 10% | M30: 125 | N30: Armor, Necklaces and Rings "of Invigoration"Armor Necklaces and Rings "of Recuperation" Armor, Necklaces and Rings "of Rejuvenation" Armor, Necklaces and Rings "of Renewal"
A31: =HYPERLINK("https://en.uesp.net/wiki/Skyrim:Fortify_Two-handed","Fortify Two-Handed") -> Fortify Two-Handed | B31: N | C31: - | D31: - | E31: X | F31: - | G31: X | H31: X | I31: X | J31: - | K31: - | L31: Plus 13% damage | M31: 369 | N31: Bracers/Gauntlets, Necklaces, and Rings "of Sure Grip" Ironhand Gauntlets Ring of Minor Striking
A32: =HYPERLINK("https://en.uesp.net/wiki/Skyrim:Fortify_Unarmed_Damage","Fortify Unarmed") -> Fortify Unarmed | B32: N | C32: - | D32: - | E32: - | F32: - | G32: X | H32: X | I32: - | J32: - | K32: - | L32: Plus 5 damage | M32: 88 | N32: Gloves of the Pugilist
A33: =HYPERLINK("https://en.uesp.net/wiki/Skyrim:Muffle_(effect)","Muffle") -> Muffle | B33: N | C33: - | D33: - | E33: - | F33: - | G33: - | H33: - | I33: X | J33: - | K33: - | L33: N/A | M33: 105 | N33: Boots "of Muffling"
A34: =HYPERLINK("https://en.uesp.net/wiki/Skyrim:Resist_Disease","Resist Disease") -> Resist Disease | B34: N | C34: - | D34: - | E34: X | F34: X | G34: - | H34: X | I34: - | J34: X | K34: - | L34: Plus 25% | M34: 55 | N34: Necklace of Disease Immunity Necklace of Disease Resistance
A35: =HYPERLINK("https://en.uesp.net/wiki/Skyrim:Resist_Fire","Resist Fire") -> Resist Fire | B35: N | C35: - | D35: - | E35: X | F35: - | G35: - | H35: X | I35: X | J35: X | K35: - | L35: Plus 15% | M35: 176 | N35: Boots, Necklaces, and Shields "of Dwindling Flames" Boots, Necklaces, and Shields "of Fire Abatement" Boots, Necklaces, and Shields "of Fire Suppression" Boots, Necklaces, and Shields "of Flame Suppression" Boots, Necklaces, and Shields "of the Firewalker" Boots, Necklaces, and Shields "of Resist Fire" Boots, Necklaces, and Shields "of Waning Fire" Ancient Helm of the Unburned Steel Shield of Fire Resist
A36: =HYPERLINK("https://en.uesp.net/wiki/Skyrim:Resist_Frost","Resist Frost") -> Resist Frost | B36: N | C36: - | D36: - | E36: X | F36: - | G36: - | H36: X | I36: X | J36: X | K36: - | L36: Plus 15% | M36: 186 | N36: Armor, Boots, Necklaces, and Shields "of Dwindling Frost" Armor, Boots, Necklaces, and Shields "of Frost Abatement" Armor, Boots, Necklaces, and Shields "of Frost Suppression" Armor, Boots, Necklaces, and Shields "of Resist Frost" Armor, Boots, Necklaces, and Shields "of Waning Frost" Armor, Boots, Necklaces, and Shields "of Warmth" Helm of Yngol Herebane's Fortress Necklace of Frost Resist
A37: =HYPERLINK("https://en.uesp.net/wiki/Skyrim:Resist_Magic","Resist Magic (Two Versions)") -> Resist Magic (Two Versions) | B37: N | C37: - | D37: - | E37: X | F37: - | G37: - | H37: X | I37: - | J37: X | K37: - | L37: Plus 8% | M37: 187 | N37: Necklaces, Rings, and Shields "of Dwindling Magic" Necklaces, Rings, and Shields "of Resist Magic" Necklaces, Rings, and Shields "of Waning Magic" Necklaces, Rings, and Shields "of Magic Abatement" Necklaces, Rings, and Shields "of Magic Suppression" Necklaces, Rings, and Shields "of Nullification" A second version of the effect is available from the Shield of Solitude
A38: =HYPERLINK("https://en.uesp.net/wiki/Skyrim:Resist_Poison","Resist Poison") -> Resist Poison | B38: N | C38: - | D38: - | E38: X | F38: X | G38: - | H38: X | I38: - | J38: X | K38: - | L38: Plus 15% | M38: 39 | N38: Necklace of Poison Immunity Necklace of Poison Resistance
A39: =HYPERLINK("https://en.uesp.net/wiki/Skyrim:Resist_Shock","Resist Shock") -> Resist Shock | B39: N | C39: - | D39: - | E39: X | F39: - | G39: - | H39: X | I39: X | J39: X | K39: - | L39: Plus 15% | M39: 196 | N39: Boots, Necklaces, and Shields "of Dwindling Shock" Boots, Necklaces, and Shields "of Grounding" Boots, Necklaces, and Shields "of Resist Shock" Boots, Necklaces, and Shields "of Shock Abatement" Boots, Necklaces, and Shields "of Shock Suppression" Boots, Necklaces, and Shields "of Waning Shock"
A40: =HYPERLINK("https://en.uesp.net/wiki/Skyrim:Waterbreathing_(effect)","Waterbreathing") -> Waterbreathing | B40: N | C40: - | D40: X | E40: X | F40: - | G40: - | H40: X | I40: - | J40: - | K40: - | L40: N/A | M40: 100 | N40: Circlets, Helmets, and Necklaces "of Waterbreathing"
...

Sheet Spells
A1: Name | B1: Obtained? | C1: School | D1: Level | E1: Value | F1: Description | G1: Location | H1: Tome ID
A2: - | B2: =(countif(B3:B116,"Y")/(Rows(B3:B170)-1)) -> 0.011976048 | C2: - | D2: - | E2: - | F2: - | G2: - | H2: -
A3: =HYPERLINK("https://en.uesp.net/wiki/Skyrim:Candlelight", "Candlelight") -> Candlelight | B3: N | C3: Alteration | D3: (1) - Novice | E3: 44 | F3: Create hovering light that lasts 60 seconds | G3: Purchase from CUK, FFH, FDR, MWH, NFH, SBP, TCW, WPK, WMK | H3: 0009E2A7
A4: =HYPERLINK("https://en.uesp.net/wiki/Skyrim:Equilibrium", "Equilibrium") -> Equilibrium | B4: N | C4: Alteration | D4: (1) - Novice | E4: 250 | F4: Convert 20/s Health into 20/s Magicka | G4: Found in Labyrinthian Chasm | H4: 000F4997
A5: =HYPERLINK("https://en.uesp.net/wiki/Skyrim:Oakflesh", "Oakflesh") -> Oakflesh | B5: N | C5: Alteration | D5: (1) - Novice | E5: 44 | F5: Improves caster's armor by 40 points for 60 seconds | G5: Purchase from CUK, FFH, FDR, MWH, NFH, RT, SBP, TCW, WPK, WMK | H5: 0009E2A8
A6: =HYPERLINK("https://en.uesp.net/wiki/Skyrim:Magelight", "Magelight") -> Magelight | B6: N | C6: Alteration | D6: (2) - Apprentice | E6: 87 | F6: Stick a 60-second ball of light where it strikes when cast | G6: Purchase from CUK, FFH, FDR, MWH, SBP, TCW, WPK, WMK | H6: 000A26E2
A7: =HYPERLINK("https://en.uesp.net/wiki/Skyrim:Stoneflesh", "Stoneflesh") -> Stoneflesh | B7: N | C7: Alteration | D7: (2) - Apprentice | E7: 95 | F7: Improves caster's armor by 60 points for 60 seconds | G7: Purchase from CUK, FFH, FDR, MWH, SBP, TCW, WPK, WMK | H7: 000A26E3
A8: =HYPERLINK("https://en.uesp.net/wiki/Skyrim:Ash_Shell", "Ash Shell (DB)") -> Ash Shell (DB) | B8: N | C8: Alteration | D8: (3) - Adept | E8: 425 | F8: (DB) Cast on a nearby surface, it explodes when enemies are nearby, immobilizing them in hardened ash for 30 seconds | G8: Purchase from TTM after "From the Ashes" quest | H8: XX0177AC
A9: =HYPERLINK("https://en.uesp.net/wiki/Skyrim:Detect_Life", "Detect Life") -> Detect Life | B9: N | C9: Alteration | D9: (3) - Adept | E9: 332 | F9: See nearby living through walls | G9: Purchase from TCW, WMK (level 40 Alteration) | H9: 000A26E7
A10: =HYPERLINK("https://en.uesp.net/wiki/Skyrim:Ironflesh", "Ironflesh") -> Ironflesh | B10: N | C10: Alteration | D10: (3) - Adept | E10: 341 | F10: Improves caster's armor by 80 points for 60 seconds | G10: Purchase from TCW, WMK (level 40 Alteration) | H10: 000A26E4
A11: =HYPERLINK("https://en.uesp.net/wiki/Skyrim:Telekinesis", "Telekinesis") -> Telekinesis | B11: N | C11: Alteration | D11: (3) - Adept | E11: 326 | F11: Target item and hover it nearer or cast it away | G11: Purchase from TCW, WMK (level 40 Alteration) | H11: 000A26E5
A12: =HYPERLINK("https://en.uesp.net/wiki/Skyrim:Transmute_Mineral_Ore", "Transmute Mineral Ore") -> Transmute Mineral Ore | B12: N | C12: Alteration | D12: (3) - Adept | E12: 200 | F12: Transmute one piece of unrefined Iron Ore to Silver Ore or Silver Ore to Gold Ore | G12: Found in Ansilvund Burial Chambers, Halted Stream Camp | H12: 00109112
A13: =HYPERLINK("https://en.uesp.net/wiki/Skyrim:Alteration_Spells#Waterbreathing", "Waterbreathing") -> Waterbreathing | B13: N | C13: Alteration | D13: (3) - Adept | E13: 340 | F13: Breathe under water for 60 seconds | G13: Purchase from TCW, WMK (level 40 Alteration) | H13: 000A26E6
A14: =HYPERLINK("https://en.uesp.net/wiki/Skyrim:Ash_Rune", "Ash Rune (DB)") -> Ash Rune (DB) | B14: N | C14: Alteration | D14: (4) - Expert | E14: 635 | F14: (DB) Targets that fail to resist are immobilized in hardened ash for 30 seconds | G14: Purchase from TTM after "From the Ashes" quest | H14: XX0177B5
A15: =HYPERLINK("https://en.uesp.net/wiki/Skyrim:Detect_Dead", "Detect Dead") -> Detect Dead | B15: N | C15: Alteration | D15: (4) - Expert | E15: 600 | F15: See nearby dead through walls | G15: Purchase from TCW (level 65 Alteration) | H15: 000A26EA
A16: =HYPERLINK("https://en.uesp.net/wiki/Skyrim:Ebonyflesh", "Ebonyflesh") -> Ebonyflesh | B16: N | C16: Alteration | D16: (4) - Expert | E16: 650 | F16: Improves caster's armor by 100 points for 60 seconds | G16: Purchase from TCW (level 65 Alteration) | H16: 000A26E9
A17: =HYPERLINK("https://en.uesp.net/wiki/Skyrim:Paralyze_(spell)", "Paralyze") -> Paralyze | B17: N | C17: Alteration | D17: (4) - Expert | E17: 685 | F17: Targets that fail to resist are paralyzed for 10 sec | G17: Purchase from TCW (level 65 Alteration) | H17: 000A26E8
A18: =HYPERLINK("https://en.uesp.net/wiki/Skyrim:Dragonhide", "Dragonhide") -> Dragonhide | B18: N | C18: Alteration | D18: (5) - Master | E18: 1389 | F18: Caster ignores 80% of physical damage for 30 seconds | G18: Reward for "Alteration Ritual Spell" quest (level 90 Alteration) | H18: 000D2B4E
A19: =HYPERLINK("https://en.uesp.net/wiki/Skyrim:Mass_Paralysis", "Mass Paralysis") -> Mass Paralysis | B19: N | C19: Alteration | D19: (5) - Master | E19: 1280 | F19: All targets in the area that fail to resist are paralyzed for 15 sec | G19: Purchase from TCW after "Alteration Ritual Spell" (Level 90 Alteration) | H19: 000DD646
A20: =HYPERLINK("https://en.uesp.net/wiki/Skyrim:Bound_Dagger", "Bound Dagger (DB)") -> Bound Dagger (DB) | B20: N | C20: Conjuration | D20: (1) - Novice | E20: 38 | F20: (DB) Creates a magic dagger for 120 seconds. Sheathe it to dispel | G20: Purchase from TTM after "From the Ashes" quest | H20: XX01CE07
A21: =HYPERLINK("https://en.uesp.net/wiki/Skyrim:Bound_Sword", "Bound Sword") -> Bound Sword | B21: N | C21: Conjuration | D21: (1) - Novice | E21: 49 | F21: Creates magic sword for 120 seconds | G21: Purchase from CUK, FFH, FDR, MWH, NFH, SBP, PCW, WPK, WMK, TTM | H21: 0009E2A9
A22: =HYPERLINK("https://en.uesp.net/wiki/Skyrim:Conjure_Familiar", "Conjure Familiar") -> Conjure Familiar | B22: N | C22: Conjuration | D22: (1) - Novice | E22: 49 | F22: Summons a familiar for 60 seconds where the caster is pointing | G22: Purchase from CUK, FFH, FDR, MWH, NFH, SBP, PCW, WPK, WMK, TTM | H22: 0009E2AB
A23: =HYPERLINK("https://en.uesp.net/wiki/Skyrim:Raise_Zombie", "Raise Zombie") -> Raise Zombie | B23: N | C23: Conjuration | D23: (1) - Novice | E23: 49 | F23: Reanimate a weak dead body to fight for 60 seconds | G23: Purchase from CUK, FFH, FDR, MWH, NFH, RT, SBP, PCW, WPK, WMK, TTM | H23: 0009E2AA
A24: =HYPERLINK("https://en.uesp.net/wiki/Skyrim:Summon_Unbound_Dremora","Summon Unbound Dremora") -> Summon Unbound Dremora | B24: N | C24: Conjuration | D24: (1) - Novice | E24: N/A | F24: Summons an unbound Dremora for 999 seconds. | G24: Learned during the quest "Conjuration Ritual Spell" (level 90 Conjuration) | H24: N/A
A25: =HYPERLINK("https://en.uesp.net/wiki/Skyrim:Bound_Battleaxe", "Bound Battleaxe") -> Bound Battleaxe | B25: N | C25: Conjuration | D25: (2) - Apprentice | E25: 99 | F25: Creates a magic battleaxe for 120 seconds | G25: Purchase from CUK, FFH, FDR, MWH, NFH, SBP, PCW, WPK, WMK, TTM | H25: 000A26ED
A26: =HYPERLINK("https://en.uesp.net/wiki/Skyrim:Conjure_Boneman", "Conjure Boneman (DG)") -> Conjure Boneman (DG) | B26: N | C26: Conjuration | D26: (2) - Apprentice | E26: 75 | F26: (DG) Summons a Boneman Archer from the Soul Cairn for 60 seconds wherever the caster is pointing | G26: Found in Soul Cairn, in the center of the encircling pathways southwest of Jiub's Opus, Page 9 | H26: XX0045B0
A27: =HYPERLINK("https://en.uesp.net/wiki/Skyrim:Conjure_Flame_Atronach", "Conjure Flame Atronach") -> Conjure Flame Atronach | B27: N | C27: Conjuration | D27: (2) - Apprentice | E27: 99 | F27: Summons a flame atronach for 60 seconds where the caster is pointing | G27: Purchase from CUK, FFH, FDR, MWH, NFH, SBP, PCW, WPK, WMK, TTM | H27: 000A26EC
A28: =HYPERLINK("https://en.uesp.net/wiki/Skyrim:Reanimate_Corpse", "Reanimate Corpse") -> Reanimate Corpse | B28: N | C28: Conjuration | D28: (2) - Apprentice | E28: 99 | F28: Reanimate a more powerful dead body to fight for 60 seconds | G28: Purchase from CUK, FFH, FDR, MWH, NFH, SBP, PCW, WPK, WMK, TTM | H28: 000A26EB
A29: =HYPERLINK("https://en.uesp.net/wiki/Skyrim:Conjuration_Spells#Soul_Trap", "Soul Trap") -> Soul Trap | B29: N | C29: Conjuration | D29: (2) - Apprentice | E29: 100 | F29: Fills a soul gem if target dies within 60 seconds of casting | G29: Purchase from CUK, FFH, FDR, MWH, NFH, SBP, PCW, WPK, WMK, TTM | H29: 0009CD54
A30: =HYPERLINK("https://en.uesp.net/wiki/Skyrim:Summon_Arniel%27s_Shade","Summon Arniel's Shade") -> Summon Arniel's Shade | B30: N | C30: Conjuration | D30: (2) - Apprentice | E30: N/A | F30: Summons the Shade of Arniel Gane for 60 seconds wherever the caster is pointing. | G30: Reward for "Arniel's Endeavor" quest | H30: N/A
A31: =HYPERLINK("https://en.uesp.net/wiki/Skyrim:Summon_Arvak", "Summon Arvak (DG)") -> Summon Arvak (DG) | B31: N | C31: Conjuration | D31: (2) - Apprentice | E31: N/A | F31: (DG) Summons Arvak in the Soul Cairn or Tamriel wilderness to act as your steed | G31: Reward for "Soul Cairn Horse" quest | H31: N/A
A32: =HYPERLINK("https://en.uesp.net/wiki/Skyrim:Banish_Daedra", "Banish Daedra") -> Banish Daedra | B32: N | C32: Conjuration | D32: (3) - Adept | E32: 346 | F32: Returns weaker daedra to Oblivion | G32: Purchase from CUK, FFH, PCW (level 40 Conjuration) | H32: 000A26EE
A33: =HYPERLINK("https://en.uesp.net/wiki/Skyrim:Bound_Bow", "Bound Bow") -> Bound Bow | B33: N | C33: Conjuration | D33: (3) - Adept | E33: 335 | F33: Creates a magic bow for 120 seconds | G33: Purchase from CUK, FFH, PCW (level 40 Conjuration) | H33: 000A26F1
A34: =HYPERLINK("https://en.uesp.net/wiki/Skyrim:Conjure_Ash_Spawn", "Conjure Ash Spawn (DB)") -> Conjure Ash Spawn (DB) | B34: N | C34: Conjuration | D34: (3) - Adept | E34: 338 | F34: (DB) Summons an Ash Spawn for 60 seconds wherever the caster is pointing | G34: Purchase from TTM after "Telvanni Research" quest | H34: XX01E2B1
A35: =HYPERLINK("https://en.uesp.net/wiki/Skyrim:Conjure_Frost_Atronach", "Conjure Frost Atronach") -> Conjure Frost Atronach | B35: N | C35: Conjuration | D35: (3) - Adept | E35: 347 | F35: Summons a frost atronach for 60 seconds where the caster is pointing | G35: Purchase from CUK, FFH, PCW (level 40 Conjuration) | H35: 000A26EF
A36: =HYPERLINK("https://en.uesp.net/wiki/Skyrim:Conjure_Mistman", "Conjure Mistman (DG)") -> Conjure Mistman (DG) | B36: N | C36: Conjuration | D36: (3) - Adept | E36: 75 | F36: (DG) Summons a Mistman from the Soul Cairn for 60 seconds wherever the caster is pointing | G36: Found in Soul Cairn next to Jiub's Opus, Page 7 | H36: XX0045B1
A37: =HYPERLINK("https://en.uesp.net/wiki/Skyrim:Conjure_Seeker", "Conjure Seeker (DB)") -> Conjure Seeker (DB) | B37: N | C37: Conjuration | D37: (3) - Adept | E37: 307 | F37: (DB) Summons a Seeker for 60 seconds wherever the caster is pointing | G37: Found in Apocrypha in multiple places (level 40 Conjuration) | H37: XX033C67
A38: =HYPERLINK("https://en.uesp.net/wiki/Skyrim:Flaming_Familiar", "Flaming Familiar") -> Flaming Familiar | B38: N | C38: Conjuration | D38: (3) - Adept | E38: 250 | F38: Summons flaming familiar that attacks then explodes causing flame damage | G38: Reward for "A Scroll For Anska" quest | H38: 000B45F7
A39: =HYPERLINK("https://en.uesp.net/wiki/Skyrim:Revenant", "Revenant") -> Revenant | B39: N | C39: Conjuration | D39: (3) - Adept | E39: 340 | F39: Reanimate a powerful dead body to fight for 60 seconds | G39: Purchase from CUK, FFH, PCW (level 40 Conjuration) | H39: 000A26F2
A40: =HYPERLINK("https://en.uesp.net/wiki/Skyrim:Command_Daedra", "Command Daedra") -> Command Daedra | B40: N | C40: Conjuration | D40: (4) - Expert | E40: 660 | F40: Powerful summoned & raised creatures are put under your control | G40: Purchase from PCW (level 65 Conjuration) | H40: 000A26F6
...

Sheet Dragon Shouts
A1: Obtained? | B1: Word of Power | C1: Translation | D1: Word Wall Location
A2: =countif(A4:A110,"*Y*")/81 -> 0
B3: =HYPERLINK("https://en.uesp.net/wiki/Skyrim:Animal_Allegiance", "Animal Allegiance") -> Animal Allegiance
A4: N | B4: Raan | C4: Animal | D4: =HYPERLINK("https://en.uesp.net/wiki/Skyrim:Ancient%27s_Ascent","Ancient's Ascent") -> Ancient's Ascent
A5: N | B5: Mir | C5: Allegiance | D5: =HYPERLINK("https://en.uesp.net/wiki/Skyrim:Angarvunde","Angarvunde") -> Angarvunde
A6: N | B6: Tah | C6: Pack | D6: =HYPERLINK("https://en.uesp.net/wiki/Skyrim:Ysgramor%27s_Tomb","Ysgramor's Tomb") -> Ysgramor's Tomb
B7: =HYPERLINK("https://en.uesp.net/wiki/Skyrim:Aura_Whisper", "Aura Whisper") -> Aura Whisper
A8: N | B8: Laas | C8: Life | D8: =HYPERLINK("https://en.uesp.net/wiki/Skyrim:Northwind_Summit","Northwind Summit") -> Northwind Summit
A9: N | B9: Yah | C9: Seek | D9: =HYPERLINK("https://en.uesp.net/wiki/Skyrim:Valthume","Valthume") -> Valthume
A10: N | B10: Nir | C10: Hunt | D10: =HYPERLINK("https://en.uesp.net/wiki/Skyrim:Volunruud","Volunruud") -> Volunruud
B11: =HYPERLINK("https://en.uesp.net/wiki/Skyrim:Become_Ethereal", "Become Ethereal") -> Become Ethereal
A12: N | B12: Feim | C12: Fade | D12: =HYPERLINK("https://en.uesp.net/wiki/Skyrim:Ironbind_Barrow","Ironbind Barrow") -> Ironbind Barrow
A13: N | B13: Zii | C13: Spirit | D13: =HYPERLINK("https://en.uesp.net/wiki/Skyrim:Lost_Valley_Redoubt","Lost Valley Redoubt") -> Lost Valley Redoubt
A14: N | B14: Gron | C14: Bind | D14: =HYPERLINK("https://en.uesp.net/wiki/Skyrim:The_Horn_of_Jurgen_Windcaller","Ustengrav - During The Horn of Jurgen Windcaller") -> Ustengrav - During The Horn of Jurgen Windcaller
B15: =HYPERLINK("https://en.uesp.net/wiki/Skyrim:Call_Dragon", "Call Dragon") -> Call Dragon
A16: N | B16: Od | C16: Snow | D16: =HYPERLINK("https://en.uesp.net/wiki/Skyrim:The_Fallen","High Hrothgar - During The Fallen") -> High Hrothgar - During The Fallen
A17: N | B17: Ah | C17: Hunter
A18: N | B18: Viing | C18: Wing
B19: =HYPERLINK("https://en.uesp.net/wiki/Skyrim:Call_of_Valor", "Call of Valor") -> Call of Valor
A20: N | B20: Hun | C20: Hero | D20: =HYPERLINK("https://en.uesp.net/wiki/Skyrim:Dragonslayer","Sovngarde - During Dragonslayer") -> Sovngarde - During Dragonslayer
A21: N | B21: Kaal | C21: Champion
A22: N | B22: Zoor | C22: Legend
B23: =HYPERLINK("https://en.uesp.net/wiki/Skyrim:Clear_Skies", "Clear Skies") -> Clear Skies
A24: N | B24: Lok | C24: Sky | D24: =HYPERLINK("https://en.uesp.net/wiki/Skyrim:Throat_of_the_World","High Hrothgar - During The Throat of the World") -> High Hrothgar - During The Throat of the World
A25: N | B25: Vah | C25: Spring
A26: N | B26: Koor | C26: Summer
B27: =HYPERLINK("https://en.uesp.net/wiki/Skyrim:Disarm", "Disarm") -> Disarm
A28: N | B28: Zun | C28: Weapon | D28: =HYPERLINK("https://en.uesp.net/wiki/Skyrim:Eldersblood_Peak","Eldersblood Peak") -> Eldersblood Peak
A29: N | B29: Haal | C29: Hand | D29: =HYPERLINK("https://en.uesp.net/wiki/Skyrim:Silverdrift_Lair","Silverdrift Lair") -> Silverdrift Lair
A30: N | B30: Viik | C30: Defeat | D30: =HYPERLINK("https://en.uesp.net/wiki/Skyrim:Speaking_With_Silence","Snow Veil Sanctum (quest locked)") -> Snow Veil Sanctum (quest locked)
B31: =HYPERLINK("https://en.uesp.net/wiki/Skyrim:Dismay", "Dismay") -> Dismay
A32: N | B32: Faas | C32: Fear | D32: =HYPERLINK("https://en.uesp.net/wiki/Skyrim:Dead_Crone_Rock","Dead Crone Rock") -> Dead Crone Rock
A33: N | B33: Ru | C33: Run | D33: =HYPERLINK("https://en.uesp.net/wiki/Skyrim:Lost_Tongue_Overlook","Lost Tongue Overlook") -> Lost Tongue Overlook
A34: N | B34: Maar | C34: Terror | D34: =HYPERLINK("https://en.uesp.net/wiki/Skyrim:Shalidor%27s_Maze","Shalidor's Maze") -> Shalidor's Maze
B35: =HYPERLINK("https://en.uesp.net/wiki/Skyrim:Dragonrend", "Dragonrend") -> Dragonrend
A36: N | B36: Joor | C36: Mortal | D36: =HYPERLINK("https://en.uesp.net/wiki/Skyrim:Throat_of_the_World","Throat of the World - During Alduin's Bane") -> Throat of the World - During Alduin's Bane
A37: N | B37: Zah | C37: Finite
A38: N | B38: Frul | C38: Temporary
B39: =HYPERLINK("https://en.uesp.net/wiki/Skyrim:Elemental_Fury", "Elemental Fury") -> Elemental Fury
A40: N | B40: Su | C40: Air | D40: =HYPERLINK("https://en.uesp.net/wiki/Skyrim:Dragontooth_Crater","Dragontooth Crater") -> Dragontooth Crater
...

Sheet Locations
A1: Location Name | B1: Location Category | C1: Region | D1: Discovered? | E1: Visited? | F1: Cleared?
A2: * indicates additional info. Refer to the wiki link under "bugs" or a note inside a cell | G2: HIDDEN
A3: Vanilla Locations | G3: Count total %
A4: Location Name | B4: Location Category | C4: Region | D4: Discovered? | E4: Visited? | F4: Cleared? | G4: =countif(D6:F478,"Y")/(countif(D6:F478,"Y") + countif(D6:F478,"N")) -> 0
A5: - | B5: - | C5: - | D5: =COUNTIF(D6:D365,"Y")/(COUNTIF(D6:D365,"Y") + COUNTIF(D6:D365,"N")) -> 0 | E5: =COUNTIF(E6:E365,"Y")/(COUNTIF(E6:E365,"Y") + COUNTIF(E6:E365,"N")) -> 0 | F5: =COUNTIF(F6:F365,"Y")/(COUNTIF(F6:F365,"Y") + COUNTIF(F6:F365,"N")) -> 0
A6: =HYPERLINK("https://en.uesp.net/wiki/Skyrim:Abandoned_Prison","Abandoned Prison") -> Abandoned Prison | B6: Imperial Tower | C6: Eastmarch | D6: N | E6: N | F6: N
A7: =HYPERLINK("https://en.uesp.net/wiki/Skyrim:Abandoned_Shack","Abandoned Shack") -> Abandoned Shack | B7: Shack | C7: Hjaalmarch | D7: N | E7: N | F7: -
A8: =HYPERLINK("https://en.uesp.net/wiki/Skyrim:Alchemist%27s_Shack","Alchemist's Shack") -> Alchemist's Shack | B8: Shack | C8: The Rift | D8: N | E8: N | F8: -
A9: =HYPERLINK("https://en.uesp.net/wiki/Skyrim:Alftand","Alftand") -> Alftand | B9: Dwarven Ruin | C9: Winterhold | D9: N | E9: N | F9: N
A10: =HYPERLINK("https://en.uesp.net/wiki/Skyrim:Ancient%27s_Ascent","Ancient's Ascent") -> Ancient's Ascent | B10: Dragon Lair | C10: Falkreath Hold | D10: N | E10: N | F10: N
A11: =HYPERLINK("https://en.uesp.net/wiki/Skyrim:Anga%27s_Mill","Anga's Mill") -> Anga's Mill | B11: Wood Mill | C11: The Pale | D11: N | E11: N | F11: -
A12: =HYPERLINK("https://en.uesp.net/wiki/Skyrim:Angarvunde","Angarvunde") -> Angarvunde | B12: Nordic Ruin | C12: Eastmarch | D12: N | E12: N | F12: N
A13: =HYPERLINK("https://en.uesp.net/wiki/Skyrim:Angi%27s_Camp","Angi's Camp") -> Angi's Camp | B13: Shack | C13: Falkreath Hold | D13: N | E13: N | F13: -
A14: =HYPERLINK("https://en.uesp.net/wiki/Skyrim:Anise%27s_Cabin","Anise's Cabin") -> Anise's Cabin | B14: Shack | C14: Falkreath Hold | D14: N | E14: N | F14: -
A15: =HYPERLINK("https://en.uesp.net/wiki/Skyrim:Ansilvund","Ansilvund") -> Ansilvund | B15: Nordic Ruin | C15: Eastmarch | D15: N | E15: N | F15: N
A16: =HYPERLINK("https://en.uesp.net/wiki/Skyrim:Arcwind_Point","Arcwind Point") -> Arcwind Point | B16: Nordic Ruin | C16: The Rift | D16: N | E16: N | F16: N
A17: =HYPERLINK("https://en.uesp.net/wiki/Skyrim:Autumnshade_Clearing","Autumnshade Clearing") -> Autumnshade Clearing | B17: Clearing | C17: The Rift | D17: N | E17: N | F17: N
A18: =HYPERLINK("https://en.uesp.net/wiki/Skyrim:Autumnwatch_Tower","Autumnwatch Tower") -> Autumnwatch Tower | B18: Dragon Lair | C18: The Rift | D18: N | E18: N | F18: N
A19: =HYPERLINK("https://en.uesp.net/wiki/Skyrim:Avanchnzel","Avanchnzel") -> Avanchnzel | B19: Dwarven Ruin | C19: The Rift | D19: N | E19: N | F19: N
A20: =HYPERLINK("https://en.uesp.net/wiki/Skyrim:Bannermist_Tower","Bannermist Tower") -> Bannermist Tower | B20: Nordic Tower | C20: Falkreath Hold | D20: N | E20: N | F20: N
A21: =HYPERLINK("https://en.uesp.net/wiki/Skyrim:Bard%27s_Leap_Summit","Bard's Leap Summit") -> Bard's Leap Summit | B21: Landmark | C21: The Reach | D21: N | E21: N | F21: -
A22: =HYPERLINK("https://en.uesp.net/wiki/Skyrim:Battle-Born_Farm","Battle-Born Farm") -> Battle-Born Farm | B22: Wheat Mill | C22: Whiterun Hold | D22: N | E22: N | F22: -
A23: =HYPERLINK("https://en.uesp.net/wiki/Skyrim:Bilegulch_Mine","Bilegulch Mine") -> Bilegulch Mine | B23: Mine | C23: Falkreath Hold | D23: N | E23: N | F23: N
A24: =HYPERLINK("https://en.uesp.net/wiki/Skyrim:Black-Briar_Lodge","Black-Briar Lodge") -> Black-Briar Lodge | B24: Settlement | C24: The Rift | D24: N | E24: N | F24: -
A25: =HYPERLINK("https://en.uesp.net/wiki/Skyrim:Bleak_Falls_Barrow_(place)","Bleak Falls Barrow") -> Bleak Falls Barrow | B25: Nordic Ruin | C25: Falkreath Hold | D25: N | E25: N | F25: N
A26: =HYPERLINK("https://en.uesp.net/wiki/Skyrim:Bleakcoast_Cave","Bleakcoast Cave") -> Bleakcoast Cave | B26: Cave | C26: Winterhold | D26: N | E26: N | F26: N
A27: =HYPERLINK("https://en.uesp.net/wiki/Skyrim:Bleakwind_Basin","Bleakwind Basin") -> Bleakwind Basin | B27: Giant Camp | C27: Whiterun Hold | D27: N | E27: N | F27: N
A28: =HYPERLINK("https://en.uesp.net/wiki/Skyrim:Bleakwind_Bluff","Bleakwind Bluff") -> Bleakwind Bluff | B28: Nordic Tower | C28: The Reach | D28: N | E28: N | F28: N
A29: =HYPERLINK("https://en.uesp.net/wiki/Skyrim:Blind_Cliff_Cave","Blind Cliff Cave") -> Blind Cliff Cave | B29: Cave | C29: The Reach | D29: N | E29: N | F29: N
A30: =HYPERLINK("https://en.uesp.net/wiki/Skyrim:Blizzard_Rest","Blizzard Rest") -> Blizzard Rest | B30: Giant Camp | C30: The Pale | D30: N | E30: N | F30: N
A31: =HYPERLINK("https://en.uesp.net/wiki/Skyrim:Bloated_Man%27s_Grotto","Bloated Man's Grotto") -> Bloated Man's Grotto | B31: Cave | C31: Falkreath Hold | D31: N | E31: N | F31: N
A32: =HYPERLINK("https://en.uesp.net/wiki/Skyrim:Bloodlet_Throne","Bloodlet Throne") -> Bloodlet Throne | B32: Military Fort | C32: Falkreath Hold | D32: N | E32: N | F32: N
A33: =HYPERLINK("https://en.uesp.net/wiki/Skyrim:Blue_Palace","Blue Palace") -> Blue Palace | B33: Castle | C33: Haafingar | D33: N | E33: N | F33: -
A34: =HYPERLINK("https://en.uesp.net/wiki/Skyrim:Bonechill_Passage","Bonechill Passage") -> Bonechill Passage | B34: Cave | C34: Falkreath Hold | D34: N | E34: N | F34: N
